#VRML_SIM R2021b utf8
WorldInfo {
  coordinateSystem "NUE"
}
Viewpoint {
  orientation 0.9859022542218496 0.04001860897288789 -0.1624661689588031 5.492032508965395
  position -1.628421748791802 13.937582462837907 14.834272998527188
}
TexturedBackground {
}
Solid {
  translation 0 0.1 0
  rotation 0 0 1 0
  children [
    DEF FOOTBALL_SHAPE Shape {
      appearance PBRAppearance {
        baseColor 1 0 0
        roughness 1
        metalness 0
      }
      geometry Sphere {
        radius 0.1
        subdivision 3
      }
    }
  ]
  name "soccer ball"
  model "soccer ball"
  boundingObject USE FOOTBALL_SHAPE
  physics Physics {
    density -1
    mass 0.6
  }
}
DEF player_0 Robot {
  translation -1 0 0
  children [
    Emitter {
      channel 2
    }
    Receiver {
      name "player_positions_receiver"
      channel 2
    }
    GPS {
    }
    Receiver {
      name "ball_pos_receiver"
      channel 1
    }
    HingeJoint {
      jointParameters HingeJointParameters {
        axis 0 0 -1
        anchor 0 0.1 -0.15
      }
      device [
        RotationalMotor {
          name "motor_2"
        }
      ]
      endPoint Solid {
        translation 0 0.1 -0.15
        rotation -1 0 0 1.570799693899574
        children [
          DEF wheel2 Shape {
            appearance PBRAppearance {
              roughness 1
              metalness 0
            }
            geometry Cylinder {
              height 0.1
              radius 0.1
            }
          }
        ]
        name "solid(1)"
        boundingObject USE wheel2
        physics DEF wheel_physics2 Physics {
        }
      }
    }
    DEF body Transform {
      translation 0 0.11 0
      children [
        Shape {
          appearance PBRAppearance {
            baseColor 0 0 1
            roughness 1
            metalness 0
          }
          geometry Box {
            size 0.3 0.2 0.3
          }
        }
      ]
    }
    HingeJoint {
      jointParameters HingeJointParameters {
        axis 0 0 -1
        anchor 0 0.1 0.15
      }
      device [
        RotationalMotor {
          name "motor_1"
        }
      ]
      endPoint Solid {
        translation 0 0.1 0.15
        rotation 1 0 0 1.5708003061004252
        children [
          DEF wheel Shape {
            appearance PBRAppearance {
              roughness 1
              metalness 0
            }
            geometry Cylinder {
              height 0.1
              radius 0.1
            }
          }
        ]
        boundingObject USE wheel
        physics DEF wheel_physics Physics {
        }
      }
    }
  ]
  name "player_0"
  boundingObject USE body
  physics Physics {
  }
  controller "player_driver"
  controllerArgs [
    "0"
  ]
}
DEF player_1 Robot {
  translation -0.5 0 1
  rotation 0 0 0.9999999999999388 0
  children [
    Emitter {
      channel 2
    }
    Receiver {
      name "player_positions_receiver"
      channel 2
    }
    GPS {
    }
    Receiver {
      name "ball_pos_receiver"
      channel 1
    }
    HingeJoint {
      jointParameters HingeJointParameters {
        position 0.5947035236108457
        axis 0 0 -1
        anchor 0 0.1 -0.15
      }
      device [
        RotationalMotor {
          name "motor_2"
        }
      ]
      endPoint Solid {
        translation 0 0.1 -0.15
        rotation -0.9175444913870546 0.2811695562336756 -0.2811686095079416 1.6567478760102792
        children [
          DEF wheel2 Shape {
            appearance PBRAppearance {
              roughness 1
              metalness 0
            }
            geometry Cylinder {
              height 0.1
              radius 0.1
            }
          }
        ]
        name "solid(1)"
        boundingObject USE wheel2
        physics DEF wheel_physics2 Physics {
        }
      }
    }
    DEF body Transform {
      translation 0 0.11 0
      children [
        Shape {
          appearance PBRAppearance {
            baseColor 0 0 1
            roughness 1
            metalness 0
          }
          geometry Box {
            size 0.3 0.2 0.3
          }
        }
      ]
    }
    HingeJoint {
      jointParameters HingeJointParameters {
        position 0.5947038350322732
        axis 0 0 -1
        anchor 0 0.1 0.15
      }
      device [
        RotationalMotor {
          name "motor_1"
        }
      ]
      endPoint Solid {
        translation 0 0.1 0.15
        rotation 0.9175444551547368 -0.2811697014184143 -0.28116858256049315 1.6567485252937124
        children [
          DEF wheel Shape {
            appearance PBRAppearance {
              roughness 1
              metalness 0
            }
            geometry Cylinder {
              height 0.1
              radius 0.1
            }
          }
        ]
        boundingObject USE wheel
        physics DEF wheel_physics Physics {
        }
      }
    }
  ]
  name "player_1"
  boundingObject USE body
  physics Physics {
  }
  controller "player_driver"
  controllerArgs [
    "1"
  ]
}
DEF player_2 Robot {
  translation -0.5 0 -1
  rotation 0 0 0.9999999999999388 0
  children [
    Emitter {
      channel 2
    }
    Receiver {
      name "player_positions_receiver"
      channel 2
    }
    GPS {
    }
    Receiver {
      name "ball_pos_receiver"
      channel 1
    }
    HingeJoint {
      jointParameters HingeJointParameters {
        position 0.5947035236108457
        axis 0 0 -1
        anchor 0 0.1 -0.15
      }
      device [
        RotationalMotor {
          name "motor_2"
        }
      ]
      endPoint Solid {
        translation 0 0.1 -0.15
        rotation -0.9175444913870546 0.2811695562336756 -0.2811686095079416 1.6567478760102792
        children [
          DEF wheel2 Shape {
            appearance PBRAppearance {
              roughness 1
              metalness 0
            }
            geometry Cylinder {
              height 0.1
              radius 0.1
            }
          }
        ]
        name "solid(1)"
        boundingObject USE wheel2
        physics DEF wheel_physics2 Physics {
        }
      }
    }
    DEF body Transform {
      translation 0 0.11 0
      children [
        Shape {
          appearance PBRAppearance {
            baseColor 0 0 1
            roughness 1
            metalness 0
          }
          geometry Box {
            size 0.3 0.2 0.3
          }
        }
      ]
    }
    HingeJoint {
      jointParameters HingeJointParameters {
        position 0.5947038350322732
        axis 0 0 -1
        anchor 0 0.1 0.15
      }
      device [
        RotationalMotor {
          name "motor_1"
        }
      ]
      endPoint Solid {
        translation 0 0.1 0.15
        rotation 0.9175444551547368 -0.2811697014184143 -0.28116858256049315 1.6567485252937124
        children [
          DEF wheel Shape {
            appearance PBRAppearance {
              roughness 1
              metalness 0
            }
            geometry Cylinder {
              height 0.1
              radius 0.1
            }
          }
        ]
        boundingObject USE wheel
        physics DEF wheel_physics Physics {
        }
      }
    }
  ]
  name "player_1(1)"
  boundingObject USE body
  physics Physics {
  }
  controller "player_driver"
  controllerArgs [
    "2"
  ]
}
Robot {
  name "supervisor"
  controller "supervisor_controller"
  supervisor TRUE
}
Solid {
  children [
    Shape {
      appearance DEF GREEN_APPEARANCE PBRAppearance {
        baseColorMap ImageTexture {
          url [
            "https://raw.githubusercontent.com/cyberbotics/webots/R2021b/projects/objects/robotstadium/protos/textures/field_quarter_base_color.jpg"
          ]
          repeatS FALSE
          repeatT FALSE
        }
        roughness 1
        metalness 0
        normalMap ImageTexture {
          url [
            "https://raw.githubusercontent.com/cyberbotics/webots/R2021b/projects/objects/robotstadium/protos/textures/field_quarter_normal.jpg"
          ]
          repeatS FALSE
          repeatT FALSE
        }
        occlusionMap ImageTexture {
          url [
            "https://raw.githubusercontent.com/cyberbotics/webots/R2021b/projects/objects/robotstadium/protos/textures/field_quarter_occlusion.jpg"
          ]
          repeatS FALSE
          repeatT FALSE
        }
      }
      geometry IndexedFaceSet {
        coord DEF QUATER_COORDS Coordinate {
          point [
            5.2 0 3.7
            0 0 3.7
            -5.2 0 3.7
            5.2 0 0
            0 0 0
            -5.2 0 0
            5.2 0 -3.7
            0 0 -3.7
            -5.2 0 -3.7
          ]
        }
        texCoord TextureCoordinate {
          point [
            0 0
            1 0
            1 1
            0 1
          ]
        }
        coordIndex [
          3, 4, 1, 0, -1, 4, 5, 2, 1, -1
          6, 7, 4, 3, -1, 7, 8, 5, 4, -1
        ]
        texCoordIndex [
          0, 1, 2, 3, -1, 1, 0, 3, 2, -1
          3, 2, 1, 0, -1, 2, 3, 0, 1, -1
        ]
      }
      castShadows FALSE
    }
    DEF WALL_OUTSIDE Shape {
      appearance PBRAppearance {
        roughness 0.5
        metalness 0
        textureTransform TextureTransform {
          scale 5 1
        }
      }
      geometry IndexedFaceSet {
        coord DEF WALL_COORDS Coordinate {
          point [
            5.22 0 3.72
            5.2 0 3.7
            -5.22 0 3.72
            -5.2 0 3.7
            5.22 0 -3.72
            5.2 0 -3.7
            -5.22 0 -3.72
            -5.2 0 -3.7
            5.22 0.3 3.72
            5.2 0.3 3.7
            -5.22 0.3 3.72
            -5.2 0.3 3.7
            5.22 0.3 -3.72
            5.2 0.3 -3.7
            -5.22 0.3 -3.72
            -5.2 0.3 -3.7
          ]
        }
        texCoord TextureCoordinate {
          point [
            0 0
            1 0
            1 1
            0 1
          ]
        }
        coordIndex [
          4, 6, 14, 12, -1, 2, 0, 8, 10, -1, 6, 2, 10, 14, -1, 0, 4, 12, 8, -1, 9, 11, 10, 8, -1, 15, 13, 12, 14, -1, 11, 15, 14, 10, -1, 9, 8, 12, 13, -1
        ]
        texCoordIndex [
          0, 1, 2, 3, -1, 0, 1, 2, 3, -1, 0, 1, 2, 3, -1, 0, 1, 2, 3, -1, 0, 0, 0, 0, -1, 0, 0, 0, 0, -1, 0, 0, 0, 0, -1, 0, 0, 0, 0, -1
        ]
      }
    }
    DEF WALL_INSIDE Shape {
      appearance PBRAppearance {
        roughness 0.5
        metalness 0
        textureTransform TextureTransform {
          scale 5 1
        }
      }
      geometry IndexedFaceSet {
        coord USE WALL_COORDS
        texCoord TextureCoordinate {
          point [
            0 0
            1 0
            1 1
            0 1
          ]
        }
        coordIndex [
          1, 3, 11, 9, -1, 7, 5, 13, 15, -1
          3, 7, 15, 11, -1, 5, 1, 9, 13, -1
        ]
        texCoordIndex [
          0, 1, 2, 3, -1, 0, 1, 2, 3, -1
          0, 1, 2, 3, -1, 0, 1, 2, 3, -1
        ]
      }
    }
    Solid {
      translation 4.55 0 0
      children [
        DEF HORIZONTAL_POST_TRANS Transform {
          translation 0 0.85 0
          rotation 1 0 0 1.5708
          children [
            Shape {
              appearance DEF POST_APP PBRAppearance {
                roughness 0.2
                metalness 0
              }
              geometry Capsule {
                height 1.6
                radius 0.05
              }
            }
          ]
        }
        DEF RIGHT_POST_TRANS Transform {
          translation 0 0.425 -0.8
          children [
            Shape {
              appearance USE POST_APP
              geometry Cylinder {
                bottom FALSE
                height 0.85
                radius 0.05
                top FALSE
              }
            }
          ]
        }
        DEF LEFT_POST_TRANS Transform {
          translation 0 0.425 0.8
          children [
            Shape {
              appearance USE POST_APP
              geometry Cylinder {
                bottom FALSE
                height 0.85
                radius 0.05
                top FALSE
              }
            }
          ]
        }
        Shape {
          appearance DEF NET_APP PBRAppearance {
            baseColorMap ImageTexture {
              url [
                "https://raw.githubusercontent.com/cyberbotics/webots/R2021b/projects/default/worlds/textures/net.png"
              ]
              filtering 0
            }
            roughness 1
            metalness 0
          }
          geometry IndexedFaceSet {
            coord Coordinate {
              point [
                0.5 0 -0.8
                0.5 0 0.8
                0.5 0.85 0.8
                0.5 0.85 -0.8
                0.05 0 0.8
                0.05 0 -0.8
                0.05 0.85 0.8
                0.05 0.85 -0.8
              ]
            }
            texCoord TextureCoordinate {
              point [
                0 0
                28 0
                28 16
                0 16
                7 0
                7 16
                0 16
                28 0
                28 6
                0 6
              ]
            }
            coordIndex [
              0, 1, 2, 3, -1, 3, 2, 1, 0, -1, 1, 4, 6, 2, -1, 2, 6, 4, 1, -1, 0, 5, 7, 3, -1, 3, 7, 5, 0, -1, 2, 3, 7, 6, -1, 6, 7, 3, 2, -1
            ]
            texCoordIndex [
              0, 1, 2, 3, -1, 0, 1, 2, 3, -1, 0, 4, 5, 6, -1, 0, 4, 5, 6, -1, 0, 4, 5, 6, -1, 0, 4, 5, 6, -1, 0, 7, 8, 9, -1, 0, 7, 8, 9, -1
            ]
          }
        }
        Transform {
          translation 0.5 0.85 0
          rotation 1 0 0 1.5708
          children [
            DEF SMALL_HORIZONTAL_POST_SHAPE Shape {
              appearance USE POST_APP
              geometry Capsule {
                height 1.6
                radius 0.014
              }
            }
          ]
        }
        Transform {
          translation 0.5 0.007 0
          rotation 1 0 0 1.5708
          children [
            USE SMALL_HORIZONTAL_POST_SHAPE
          ]
        }
        Transform {
          translation 0.5 0.425 0.8
          children [
            DEF SMALL_POST_SHAPE Shape {
              appearance USE POST_APP
              geometry Cylinder {
                bottom FALSE
                height 0.85
                radius 0.014
                top FALSE
              }
            }
          ]
        }
        Transform {
          translation 0.5 0.425 -0.8
          children [
            USE SMALL_POST_SHAPE
          ]
        }
        Transform {
          translation 0.25 0.85 0.8
          rotation 0 0 1 1.5708
          children [
            DEF OTHER_SMALL_POST_SHAPE Shape {
              appearance USE POST_APP
              geometry Cylinder {
                bottom FALSE
                height 0.5
                radius 0.014
                top FALSE
              }
            }
          ]
        }
        Transform {
          translation 0.25 0.85 -0.8
          rotation 0 0 1 1.5708
          children [
            USE OTHER_SMALL_POST_SHAPE
          ]
        }
        Transform {
          translation 0.25 0.007 0.8
          rotation 0 0 1 1.5708
          children [
            USE OTHER_SMALL_POST_SHAPE
          ]
        }
        Transform {
          translation 0.25 0.007 -0.8
          rotation 0 0 1 1.5708
          children [
            USE OTHER_SMALL_POST_SHAPE
          ]
        }
      ]
      name "goal 1"
      model "robotstadium goal"
      boundingObject Group {
        children [
          USE HORIZONTAL_POST_TRANS
          USE RIGHT_POST_TRANS
          USE LEFT_POST_TRANS
          Transform {
            translation 0.275 0.425 -0.8
            children [
              DEF GOAL_SIDE_BOX Box {
                size 0.45 0.85 0.04
              }
            ]
          }
          Transform {
            translation 0.275 0.425 0.8
            children [
              USE GOAL_SIDE_BOX
            ]
          }
          Transform {
            translation 0.6 0.425 0
            children [
              Box {
                size 0.2 0.85 1.64
              }
            ]
          }
        ]
      }
      locked TRUE
    }
    Solid {
      translation -4.55 0 0
      rotation 0 1 0 3.14159
      children [
        DEF HORIZONTAL_POST_TRANS Transform {
          translation 0 0.85 0
          rotation 1 0 0 1.5708
          children [
            Shape {
              appearance DEF POST_APP PBRAppearance {
                roughness 0.2
                metalness 0
              }
              geometry Capsule {
                height 1.6
                radius 0.05
              }
            }
          ]
        }
        DEF RIGHT_POST_TRANS Transform {
          translation 0 0.425 -0.8
          children [
            Shape {
              appearance USE POST_APP
              geometry Cylinder {
                bottom FALSE
                height 0.85
                radius 0.05
                top FALSE
              }
            }
          ]
        }
        DEF LEFT_POST_TRANS Transform {
          translation 0 0.425 0.8
          children [
            Shape {
              appearance USE POST_APP
              geometry Cylinder {
                bottom FALSE
                height 0.85
                radius 0.05
                top FALSE
              }
            }
          ]
        }
        Shape {
          appearance DEF NET_APP PBRAppearance {
            baseColorMap ImageTexture {
              url [
                "https://raw.githubusercontent.com/cyberbotics/webots/R2021b/projects/default/worlds/textures/net.png"
              ]
              filtering 0
            }
            roughness 1
            metalness 0
          }
          geometry IndexedFaceSet {
            coord Coordinate {
              point [
                0.5 0 -0.8
                0.5 0 0.8
                0.5 0.85 0.8
                0.5 0.85 -0.8
                0.05 0 0.8
                0.05 0 -0.8
                0.05 0.85 0.8
                0.05 0.85 -0.8
              ]
            }
            texCoord TextureCoordinate {
              point [
                0 0
                28 0
                28 16
                0 16
                7 0
                7 16
                0 16
                28 0
                28 6
                0 6
              ]
            }
            coordIndex [
              0, 1, 2, 3, -1, 3, 2, 1, 0, -1, 1, 4, 6, 2, -1, 2, 6, 4, 1, -1, 0, 5, 7, 3, -1, 3, 7, 5, 0, -1, 2, 3, 7, 6, -1, 6, 7, 3, 2, -1
            ]
            texCoordIndex [
              0, 1, 2, 3, -1, 0, 1, 2, 3, -1, 0, 4, 5, 6, -1, 0, 4, 5, 6, -1, 0, 4, 5, 6, -1, 0, 4, 5, 6, -1, 0, 7, 8, 9, -1, 0, 7, 8, 9, -1
            ]
          }
        }
        Transform {
          translation 0.5 0.85 0
          rotation 1 0 0 1.5708
          children [
            DEF SMALL_HORIZONTAL_POST_SHAPE Shape {
              appearance USE POST_APP
              geometry Capsule {
                height 1.6
                radius 0.014
              }
            }
          ]
        }
        Transform {
          translation 0.5 0.007 0
          rotation 1 0 0 1.5708
          children [
            USE SMALL_HORIZONTAL_POST_SHAPE
          ]
        }
        Transform {
          translation 0.5 0.425 0.8
          children [
            DEF SMALL_POST_SHAPE Shape {
              appearance USE POST_APP
              geometry Cylinder {
                bottom FALSE
                height 0.85
                radius 0.014
                top FALSE
              }
            }
          ]
        }
        Transform {
          translation 0.5 0.425 -0.8
          children [
            USE SMALL_POST_SHAPE
          ]
        }
        Transform {
          translation 0.25 0.85 0.8
          rotation 0 0 1 1.5708
          children [
            DEF OTHER_SMALL_POST_SHAPE Shape {
              appearance USE POST_APP
              geometry Cylinder {
                bottom FALSE
                height 0.5
                radius 0.014
                top FALSE
              }
            }
          ]
        }
        Transform {
          translation 0.25 0.85 -0.8
          rotation 0 0 1 1.5708
          children [
            USE OTHER_SMALL_POST_SHAPE
          ]
        }
        Transform {
          translation 0.25 0.007 0.8
          rotation 0 0 1 1.5708
          children [
            USE OTHER_SMALL_POST_SHAPE
          ]
        }
        Transform {
          translation 0.25 0.007 -0.8
          rotation 0 0 1 1.5708
          children [
            USE OTHER_SMALL_POST_SHAPE
          ]
        }
      ]
      name "goal 2"
      model "robotstadium goal"
      boundingObject Group {
        children [
          USE HORIZONTAL_POST_TRANS
          USE RIGHT_POST_TRANS
          USE LEFT_POST_TRANS
          Transform {
            translation 0.275 0.425 -0.8
            children [
              DEF GOAL_SIDE_BOX Box {
                size 0.45 0.85 0.04
              }
            ]
          }
          Transform {
            translation 0.275 0.425 0.8
            children [
              USE GOAL_SIDE_BOX
            ]
          }
          Transform {
            translation 0.6 0.425 0
            children [
              Box {
                size 0.2 0.85 1.64
              }
            ]
          }
        ]
      }
      locked TRUE
    }
  ]
  name "robotstadium soccer field"
  model "robotstadium soccer field"
  boundingObject Group {
    children [
      Plane {
        size 10.4 7.4
      }
      Transform {
        translation 5.2 0.15 0
        rotation 0 0 1 1.5708
        children [
          Box {
            size 0.3 0.02 7.4
          }
        ]
      }
      Transform {
        translation -5.2 0.15 0
        rotation 0 0 1 -1.5708
        children [
          Box {
            size 0.3 0.02 7.4
          }
        ]
      }
      Transform {
        translation 0 0.15 3.7
        rotation 1 0 0 -1.5708
        children [
          Box {
            size 10.4 0.02 0.3
          }
        ]
      }
      Transform {
        translation 0 0.15 -3.7
        rotation 1 0 0 1.5708
        children [
          Box {
            size 10.4 0.02 0.3
          }
        ]
      }
    ]
  }
  locked TRUE
}
Robot {
  translation 0 14 0
  rotation 1 0 0 -1.5707953071795862
  children [
    Emitter {
      channel 1
    }
    Camera {
      name "CAM"
      fieldOfView 0.71205
      width 832
      height 592
    }
  ]
  name "ball_tracker"
  locked TRUE
  controller "camera_controller"
}
TexturedBackgroundLight {
  castShadows FALSE
}
