#VRML_SIM R2021b utf8
WorldInfo {
  coordinateSystem "NUE"
}
Viewpoint {
  orientation 0.949399748560853 0.2354113140846306 -0.20789812561333085 5.758238977058858
  position -1.6731327542658847 8.658407455149106 12.24006190731004
}
TexturedBackground {
}
Solid {
  translation 0 0.1 0
  rotation 0 0 1 0
  children [
    DEF FOOTBALL_SHAPE Shape {
      appearance PBRAppearance {
        baseColor 1 0 0
        roughness 1
        metalness 0
        emissiveColor 1 0 0
        emissiveIntensity 5
      }
      geometry Sphere {
        radius 0.1
        subdivision 3
      }
      castShadows FALSE
    }
  ]
  name "soccer ball"
  model "soccer ball"
  boundingObject USE FOOTBALL_SHAPE
  physics Physics {
    density -1
    mass 0.6
  }
}
DEF player_1 Robot {
  children [
    HingeJoint {
      jointParameters HingeJointParameters {
        axis 0 0 -1
        anchor -1 0.1 -0.15
      }
      device [
        RotationalMotor {
          name "motor_2"
        }
      ]
      endPoint Solid {
        translation -1 0.1 -0.15
        rotation -1 0 0 1.570799693899574
        children [
          DEF wheel2 Shape {
            appearance PBRAppearance {
              roughness 1
              metalness 0
            }
            geometry Cylinder {
              height 0.1
              radius 0.1
            }
          }
        ]
        name "solid(1)"
        boundingObject USE wheel2
        physics DEF wheel_physics2 Physics {
        }
      }
    }
    DEF body Transform {
      translation -1 0.11 0
      children [
        Shape {
          appearance PBRAppearance {
            baseColor 0 0 1
            roughness 1
            metalness 0
          }
          geometry Box {
            size 0.3 0.2 0.3
          }
        }
      ]
    }
    HingeJoint {
      jointParameters HingeJointParameters {
        axis 0 0 -1
        anchor -1 0.1 0.15
      }
      device [
        RotationalMotor {
          name "motor_1"
        }
      ]
      endPoint Solid {
        translation -1 0.1 0.15
        rotation 1 0 0 1.5708003061004252
        children [
          DEF wheel Shape {
            appearance PBRAppearance {
              roughness 1
              metalness 0
            }
            geometry Cylinder {
              height 0.1
              radius 0.1
            }
          }
        ]
        boundingObject USE wheel
        physics DEF wheel_physics Physics {
        }
      }
    }
  ]
  boundingObject USE body
  physics Physics {
  }
  controller "robot_driver"
}
RobotstadiumSoccerField {
}
DEF supervisor Robot {
  name "supervisor"
  controller "supervisor_controller"
  supervisor TRUE
}
Robot {
  translation 0 13 0
  rotation 1 0 0 -1.5707953071795862
  children [
    Camera {
      name "CAM"
      width 832
      height 592
    }
  ]
  name "top_view_camera"
  locked TRUE
  controller "camera_controller"
}
TexturedBackgroundLight {
  castShadows FALSE
}
